{"trial_id": "0001", "hyperparameters": {"space": [{"class_name": "Int", "config": {"name": "conv1_filters", "default": null, "conditions": [], "min_value": 32, "max_value": 128, "step": 32, "sampling": "linear"}}, {"class_name": "Int", "config": {"name": "conv2_filters", "default": null, "conditions": [], "min_value": 64, "max_value": 256, "step": 64, "sampling": "linear"}}, {"class_name": "Int", "config": {"name": "conv3_filters", "default": null, "conditions": [], "min_value": 64, "max_value": 256, "step": 64, "sampling": "linear"}}, {"class_name": "Int", "config": {"name": "dense1_units", "default": null, "conditions": [], "min_value": 128, "max_value": 512, "step": 128, "sampling": "linear"}}, {"class_name": "Choice", "config": {"name": "learning_rate", "default": 0.01, "conditions": [], "values": [0.01, 0.001, 0.0001], "ordered": true}}], "values": {"conv1_filters": 96, "conv2_filters": 192, "conv3_filters": 192, "dense1_units": 256, "learning_rate": 0.0001, "tuner/epochs": 2, "tuner/initial_epoch": 0, "tuner/bracket": 2, "tuner/round": 0}}, "metrics": {"metrics": {}}, "score": null, "best_step": 0, "status": "FAILED", "message": "Traceback (most recent call last):\n  File \"/home/chris-joyce/anaconda3/lib/python3.12/site-packages/keras_tuner/src/engine/base_tuner.py\", line 274, in _try_run_and_update_trial\n    self._run_and_update_trial(trial, *fit_args, **fit_kwargs)\n  File \"/home/chris-joyce/anaconda3/lib/python3.12/site-packages/keras_tuner/src/engine/base_tuner.py\", line 239, in _run_and_update_trial\n    results = self.run_trial(trial, *fit_args, **fit_kwargs)\n              ^^^^^^^^^^^^^^^^^^^^^^^^^^^^^^^^^^^^^^^^^^^^^^\n  File \"/home/chris-joyce/anaconda3/lib/python3.12/site-packages/keras_tuner/src/tuners/hyperband.py\", line 427, in run_trial\n    return super().run_trial(trial, *fit_args, **fit_kwargs)\n           ^^^^^^^^^^^^^^^^^^^^^^^^^^^^^^^^^^^^^^^^^^^^^^^^^\n  File \"/home/chris-joyce/anaconda3/lib/python3.12/site-packages/keras_tuner/src/engine/tuner.py\", line 314, in run_trial\n    obj_value = self._build_and_fit_model(trial, *args, **copied_kwargs)\n                ^^^^^^^^^^^^^^^^^^^^^^^^^^^^^^^^^^^^^^^^^^^^^^^^^^^^^^^^\n  File \"/home/chris-joyce/anaconda3/lib/python3.12/site-packages/keras_tuner/src/engine/tuner.py\", line 233, in _build_and_fit_model\n    results = self.hypermodel.fit(hp, model, *args, **kwargs)\n              ^^^^^^^^^^^^^^^^^^^^^^^^^^^^^^^^^^^^^^^^^^^^^^^\n  File \"/home/chris-joyce/anaconda3/lib/python3.12/site-packages/keras_tuner/src/engine/hypermodel.py\", line 149, in fit\n    return model.fit(*args, **kwargs)\n           ^^^^^^^^^^^^^^^^^^^^^^^^^^\n  File \"/home/chris-joyce/anaconda3/lib/python3.12/site-packages/keras/src/utils/traceback_utils.py\", line 122, in error_handler\n    raise e.with_traceback(filtered_tb) from None\n  File \"/home/chris-joyce/anaconda3/lib/python3.12/site-packages/tensorflow/python/eager/execute.py\", line 59, in quick_execute\n    except TypeError as e:\ntensorflow.python.framework.errors_impl.InvalidArgumentError: Graph execution error:\n\nDetected at node compile_loss/sparse_categorical_crossentropy/SparseSoftmaxCrossEntropyWithLogits/SparseSoftmaxCrossEntropyWithLogits defined at (most recent call last):\n  File \"/home/chris-joyce/anaconda3/lib/python3.12/runpy.py\", line 198, in _run_module_as_main\n\n  File \"/home/chris-joyce/anaconda3/lib/python3.12/runpy.py\", line 88, in _run_code\n\n  File \"/home/chris-joyce/anaconda3/lib/python3.12/site-packages/spyder_kernels/console/__main__.py\", line 24, in <module>\n\n  File \"/home/chris-joyce/anaconda3/lib/python3.12/site-packages/spyder_kernels/console/start.py\", line 331, in main\n\n  File \"/home/chris-joyce/anaconda3/lib/python3.12/site-packages/ipykernel/kernelapp.py\", line 701, in start\n\n  File \"/home/chris-joyce/anaconda3/lib/python3.12/site-packages/tornado/platform/asyncio.py\", line 205, in start\n\n  File \"/home/chris-joyce/anaconda3/lib/python3.12/asyncio/base_events.py\", line 641, in run_forever\n\n  File \"/home/chris-joyce/anaconda3/lib/python3.12/asyncio/base_events.py\", line 1987, in _run_once\n\n  File \"/home/chris-joyce/anaconda3/lib/python3.12/asyncio/events.py\", line 88, in _run\n\n  File \"/home/chris-joyce/anaconda3/lib/python3.12/site-packages/ipykernel/kernelbase.py\", line 534, in dispatch_queue\n\n  File \"/home/chris-joyce/anaconda3/lib/python3.12/site-packages/ipykernel/kernelbase.py\", line 523, in process_one\n\n  File \"/home/chris-joyce/anaconda3/lib/python3.12/site-packages/ipykernel/kernelbase.py\", line 429, in dispatch_shell\n\n  File \"/home/chris-joyce/anaconda3/lib/python3.12/site-packages/ipykernel/kernelbase.py\", line 767, in execute_request\n\n  File \"/home/chris-joyce/anaconda3/lib/python3.12/site-packages/ipykernel/ipkernel.py\", line 429, in do_execute\n\n  File \"/home/chris-joyce/anaconda3/lib/python3.12/site-packages/ipykernel/zmqshell.py\", line 549, in run_cell\n\n  File \"/home/chris-joyce/anaconda3/lib/python3.12/site-packages/IPython/core/interactiveshell.py\", line 3075, in run_cell\n\n  File \"/home/chris-joyce/anaconda3/lib/python3.12/site-packages/IPython/core/interactiveshell.py\", line 3130, in _run_cell\n\n  File \"/home/chris-joyce/anaconda3/lib/python3.12/site-packages/IPython/core/async_helpers.py\", line 129, in _pseudo_sync_runner\n\n  File \"/home/chris-joyce/anaconda3/lib/python3.12/site-packages/IPython/core/interactiveshell.py\", line 3334, in run_cell_async\n\n  File \"/home/chris-joyce/anaconda3/lib/python3.12/site-packages/IPython/core/interactiveshell.py\", line 3517, in run_ast_nodes\n\n  File \"/home/chris-joyce/anaconda3/lib/python3.12/site-packages/IPython/core/interactiveshell.py\", line 3577, in run_code\n\n  File \"/tmp/ipykernel_4876/3132901864.py\", line 1, in <module>\n\n  File \"/home/chris-joyce/anaconda3/lib/python3.12/site-packages/spyder_kernels/customize/spydercustomize.py\", line 528, in runfile\n\n  File \"/home/chris-joyce/anaconda3/lib/python3.12/site-packages/spyder_kernels/customize/spydercustomize.py\", line 615, in _exec_file\n\n  File \"/home/chris-joyce/anaconda3/lib/python3.12/site-packages/spyder_kernels/customize/spydercustomize.py\", line 473, in exec_code\n\n  File \"/home/chris-joyce/anaconda3/lib/python3.12/site-packages/spyder_kernels/py3compat.py\", line 356, in compat_exec\n\n  File \"/home/chris-joyce/Artificial_Intelligence/CNN_Model.py\", line 165, in <module>\n\n  File \"/home/chris-joyce/anaconda3/lib/python3.12/site-packages/keras_tuner/src/engine/base_tuner.py\", line 234, in search\n\n  File \"/home/chris-joyce/anaconda3/lib/python3.12/site-packages/keras_tuner/src/engine/base_tuner.py\", line 274, in _try_run_and_update_trial\n\n  File \"/home/chris-joyce/anaconda3/lib/python3.12/site-packages/keras_tuner/src/engine/base_tuner.py\", line 239, in _run_and_update_trial\n\n  File \"/home/chris-joyce/anaconda3/lib/python3.12/site-packages/keras_tuner/src/tuners/hyperband.py\", line 427, in run_trial\n\n  File \"/home/chris-joyce/anaconda3/lib/python3.12/site-packages/keras_tuner/src/engine/tuner.py\", line 314, in run_trial\n\n  File \"/home/chris-joyce/anaconda3/lib/python3.12/site-packages/keras_tuner/src/engine/tuner.py\", line 233, in _build_and_fit_model\n\n  File \"/home/chris-joyce/anaconda3/lib/python3.12/site-packages/keras_tuner/src/engine/hypermodel.py\", line 149, in fit\n\n  File \"/home/chris-joyce/anaconda3/lib/python3.12/site-packages/keras/src/utils/traceback_utils.py\", line 117, in error_handler\n\n  File \"/home/chris-joyce/anaconda3/lib/python3.12/site-packages/keras/src/backend/tensorflow/trainer.py\", line 371, in fit\n\n  File \"/home/chris-joyce/anaconda3/lib/python3.12/site-packages/keras/src/backend/tensorflow/trainer.py\", line 219, in function\n\n  File \"/home/chris-joyce/anaconda3/lib/python3.12/site-packages/keras/src/backend/tensorflow/trainer.py\", line 132, in multi_step_on_iterator\n\n  File \"/home/chris-joyce/anaconda3/lib/python3.12/site-packages/keras/src/backend/tensorflow/trainer.py\", line 113, in one_step_on_data\n\n  File \"/home/chris-joyce/anaconda3/lib/python3.12/site-packages/keras/src/backend/tensorflow/trainer.py\", line 60, in train_step\n\n  File \"/home/chris-joyce/anaconda3/lib/python3.12/site-packages/keras/src/trainers/trainer.py\", line 383, in _compute_loss\n\n  File \"/home/chris-joyce/anaconda3/lib/python3.12/site-packages/keras/src/trainers/trainer.py\", line 351, in compute_loss\n\n  File \"/home/chris-joyce/anaconda3/lib/python3.12/site-packages/keras/src/trainers/compile_utils.py\", line 691, in __call__\n\n  File \"/home/chris-joyce/anaconda3/lib/python3.12/site-packages/keras/src/trainers/compile_utils.py\", line 700, in call\n\n  File \"/home/chris-joyce/anaconda3/lib/python3.12/site-packages/keras/src/losses/loss.py\", line 67, in __call__\n\n  File \"/home/chris-joyce/anaconda3/lib/python3.12/site-packages/keras/src/losses/losses.py\", line 33, in call\n\n  File \"/home/chris-joyce/anaconda3/lib/python3.12/site-packages/keras/src/losses/losses.py\", line 2246, in sparse_categorical_crossentropy\n\n  File \"/home/chris-joyce/anaconda3/lib/python3.12/site-packages/keras/src/ops/nn.py\", line 1963, in sparse_categorical_crossentropy\n\n  File \"/home/chris-joyce/anaconda3/lib/python3.12/site-packages/keras/src/backend/tensorflow/nn.py\", line 744, in sparse_categorical_crossentropy\n\nReceived a label value of 2 which is outside the valid range of [0, 2).  Label values: 1 1 1 1 1 1 1 1 1 1 1 1 1 1 1 1 1 1 1 1 1 1 1 1 1 2\n\t [[{{node compile_loss/sparse_categorical_crossentropy/SparseSoftmaxCrossEntropyWithLogits/SparseSoftmaxCrossEntropyWithLogits}}]] [Op:__inference_multi_step_on_iterator_5475]\n"}